package sheenrox82.RioV.src.world.feature;

import java.util.Random;

import net.minecraft.world.World;
import net.minecraft.world.gen.feature.WorldGenerator;

public class WorldGenShrine extends WorldGenerator
{

	@Override
	public boolean generate(World var1, Random var2, int var3, int var4, int var5) 
	{
		return false;
	}
	
	/**protected int[] GetValidSpawnBlocks() {
		return new int[] {
			Block.grass.blockID,
		};
	}

	public boolean LocationIsValidSpawn(World world, int i, int j, int k){
		int distanceToAir = 0;
		int checkID = world.getBlockId(i, j, k);

		while (checkID != 0){
			distanceToAir++;
			checkID = world.getBlockId(i, j + distanceToAir, k);
		}

		if (distanceToAir > 3){
			return false;
		}
		j += distanceToAir - 1;

		int blockID = world.getBlockId(i, j, k);
		int blockIDAbove = world.getBlockId(i, j+1, k);
		int blockIDBelow = world.getBlockId(i, j-1, k);
		for (int x : GetValidSpawnBlocks()){
			if (blockIDAbove != 0){
				return false;
			}
			if (blockID == x){
				return true;
			}else if (blockID == Block.snow.blockID && blockIDBelow == x){
				return true;
			}
		}
		return false;
	}

	public WorldGenShrine() { }

	public boolean generate(World world, Random rand, int i, int j, int k) {
		//check that each corner is one of the valid spawn blocks
		if(!LocationIsValidSpawn(world, i, j, k) || !LocationIsValidSpawn(world, i + 8, j, k) || !LocationIsValidSpawn(world, i + 8, j, k + 8) || !LocationIsValidSpawn(world, i, j, k + 8))
		{
			return false;
		}

		world.setBlock(i + 0, j + 0, k + 3, Block.silverfish.blockID);
		world.setBlock(i + 1, j + 0, k + 2, Block.silverfish.blockID);
		world.setBlock(i + 1, j + 0, k + 3, Block.silverfish.blockID);
		world.setBlock(i + 1, j + 0, k + 6, Block.silverfish.blockID);
		world.setBlock(i + 1, j + 1, k + 2, Block.silverfish.blockID);
		world.setBlock(i + 1, j + 1, k + 3, Block.silverfish.blockID);
		world.setBlock(i + 2, j + 0, k + 1, Block.silverfish.blockID);
		world.setBlock(i + 2, j + 0, k + 2, Block.silverfish.blockID);
		world.setBlock(i + 2, j + 0, k + 3, Block.silverfish.blockID);
		world.setBlock(i + 2, j + 0, k + 4, Block.silverfish.blockID);
		world.setBlock(i + 2, j + 0, k + 5, Block.silverfish.blockID);
		world.setBlock(i + 2, j + 0, k + 6, Block.silverfish.blockID);
		world.setBlock(i + 2, j + 0, k + 7, Block.silverfish.blockID);
		world.setBlock(i + 2, j + 1, k + 1, Block.silverfish.blockID);
		world.setBlock(i + 2, j + 1, k + 2, Block.silverfish.blockID);
		world.setBlock(i + 2, j + 1, k + 6, Block.stoneBrick.blockID);
		world.setBlock(i + 2, j + 1, k + 7, Block.silverfish.blockID);
		world.setBlock(i + 2, j + 2, k + 1, Block.silverfish.blockID);
		world.setBlock(i + 2, j + 2, k + 2, Block.silverfish.blockID);
		world.setBlock(i + 2, j + 2, k + 6, Block.silverfish.blockID);
		world.setBlock(i + 2, j + 2, k + 7, Block.silverfish.blockID);
		world.setBlock(i + 2, j + 3, k + 1, Block.silverfish.blockID);
		world.setBlock(i + 3, j + 0, k + 0, Block.silverfish.blockID);
		world.setBlock(i + 3, j + 0, k + 2, Block.silverfish.blockID);
		world.setBlock(i + 3, j + 0, k + 4, Block.silverfish.blockID);
		world.setBlock(i + 3, j + 0, k + 5, Block.silverfish.blockID);
		world.setBlock(i + 3, j + 0, k + 6, Block.silverfish.blockID);
		world.setBlock(i + 3, j + 0, k + 7, Block.silverfish.blockID);
		world.setBlock(i + 3, j + 1, k + 7, Block.silverfish.blockID);
		world.setBlock(i + 4, j + 0, k + 0, Block.silverfish.blockID);
		world.setBlock(i + 4, j + 0, k + 2, Block.silverfish.blockID);
		world.setBlock(i + 4, j + 0, k + 3, Block.silverfish.blockID);
		world.setBlock(i + 4, j + 0, k + 4, Block.silverfish.blockID);
		world.setBlock(i + 4, j + 0, k + 5, Block.silverfish.blockID);
		world.setBlock(i + 4, j + 0, k + 6, Block.silverfish.blockID);
		world.setBlock(i + 4, j + 0, k + 7, Block.silverfish.blockID);
		world.setBlock(i + 4, j + 0, k + 8, Block.silverfish.blockID);
		world.setBlock(i + 4, j + 1, k + 4, RioVBlocks.shrine.blockID);
		world.setBlock(i + 5, j + 0, k + 2, Block.silverfish.blockID);
		world.setBlock(i + 5, j + 0, k + 3, Block.silverfish.blockID);
		world.setBlock(i + 5, j + 0, k + 4, Block.silverfish.blockID);
		world.setBlock(i + 5, j + 0, k + 5, Block.silverfish.blockID);
		world.setBlock(i + 5, j + 0, k + 6, Block.silverfish.blockID);
		world.setBlock(i + 5, j + 0, k + 7, Block.silverfish.blockID);
		world.setBlock(i + 5, j + 0, k + 8, Block.silverfish.blockID);
		world.setBlock(i + 6, j + 0, k + 1, Block.silverfish.blockID);
		world.setBlock(i + 6, j + 0, k + 2, Block.silverfish.blockID);
		world.setBlock(i + 6, j + 0, k + 3, Block.silverfish.blockID);
		world.setBlock(i + 6, j + 0, k + 5, Block.silverfish.blockID);
		world.setBlock(i + 6, j + 0, k + 6, Block.silverfish.blockID);
		world.setBlock(i + 6, j + 0, k + 7, Block.silverfish.blockID);
		world.setBlock(i + 6, j + 1, k + 1, Block.stoneBrick.blockID);
		world.setBlock(i + 6, j + 1, k + 2, Block.silverfish.blockID);
		world.setBlock(i + 6, j + 1, k + 6, Block.silverfish.blockID);
		world.setBlock(i + 6, j + 1, k + 7, Block.silverfish.blockID);
		world.setBlock(i + 6, j + 2, k + 1, Block.stoneBrick.blockID);
		world.setBlock(i + 6, j + 2, k + 2, Block.silverfish.blockID);
		world.setBlock(i + 6, j + 2, k + 6, Block.silverfish.blockID);
		world.setBlock(i + 6, j + 2, k + 7, Block.silverfish.blockID);
		world.setBlock(i + 6, j + 3, k + 1, Block.stoneBrick.blockID);
		world.setBlock(i + 6, j + 3, k + 7, Block.stoneBrick.blockID);
		world.setBlock(i + 7, j + 0, k + 2, Block.silverfish.blockID);
		world.setBlock(i + 7, j + 0, k + 3, Block.silverfish.blockID);
		world.setBlock(i + 7, j + 0, k + 4, Block.silverfish.blockID);
		world.setBlock(i + 7, j + 0, k + 5, Block.silverfish.blockID);
		world.setBlock(i + 7, j + 0, k + 6, Block.silverfish.blockID);
		world.setBlock(i + 7, j + 1, k + 2, Block.silverfish.blockID);
		world.setBlock(i + 7, j + 1, k + 3, Block.silverfish.blockID);
		world.setBlock(i + 7, j + 1, k + 6, Block.silverfish.blockID);
		world.setBlock(i + 8, j + 0, k + 4, Block.silverfish.blockID);

		return true;
	}
**/
}